Workbook

Sheet Circuits
A1: 🔒 Row ID | B1: Circuit | C1: Image | D1: Parent Category | E1: Category | F1: Reps | G1: Rest | H1: Notes | I1: Noes 2
A2: H6DtNXjKSvOQwGeFw3M6HQ | B2: Waterloo | D2: Circuits | E2: General Strength | F2: 10 reps each
A3: sTJIzbcwSfqf8DayKxa-Ng | B3: Bataan | D3: Circuits | E3: General Strength | F3: 10 reps each
A4: vWLIKjClQnKzNP4bMOVpzw | B4: Pillar | D4: Circuits | E4: General Strength | F4: 10 reps each
A5: a-9dC4hBvRqy5Cb3AAY2aRA | B5: Pedestal | D5: Circuits | E5: General Strength | F5: 10 reps each
A6: 0N4KnYZhTMKQaEP37sJK5w | B6: Verdun | D6: Circuits | E6: General Strength | F6: 20-40m each way
A8: q7lE4MpERne00Md4xr0I8w | B8: Gas | D8: Circuits | E8: Multiple Throw | F8: 10 reps each
A9: 2LkjpIs0QxWIxkSVZ7a1fA | B9: Tank | D9: Circuits | E9: Multiple Throw | F9: 10 reps each
A10: dS3QT.3CRlCctDxq.f3e5g | B10: Bomb | D10: Circuits | E10: Multiple Throw | F10: 3x 4 throws
A11: B8xj1yWjSe6KQnApSOnC3Q | B11: Grenade | D11: Circuits | E11: Multiple Throw | F11: 3x 4 throws
A12: Zxu1M7DsRQOkJJ4yS6p36g | B12: Shell | D12: Circuits | E12: Multiple Throw | F12: 3x 4 throws
A13: a.GzVlZ-KQdS8t.hk-zPF0g | B13: Mortar | D13: Circuits | E13: Multiple Throw | F13: 3x 4 throws
A15: drYtiBLyQOKlAesEtH0D8w | B15: RIP | D15: Circuits | E15: Multiple Jump | F15: 3 sets of 4 jumps
... A29: GFLZ4lCPQcK06PfjjRHeYA | B29: Ancillary D | D29: Circuits | E29: Ancillary Strength | F29: 1-3 sets of 10 reps
A31: cJxeLx3ZTZWdJohORqXw4Q | B31: WU A | D31: General | E31: Warm-Up | H31: Jog-skip 400m Static Stretch (prescribed) Sprint Drills (A & B) x 2 X 30m Dynamic Flexibility (A & B) Buildup Runs x 3-4 x 20-40m
A32: y3kZfD.qT9-2XyivtCX3iA | B32: WU B | D32: General | E32: Warm-Up | H32: Jog-skip 400m Static Stretch (prescribed) Sprint Drills (A & B) x 1 X 20m Dynamic Flexibility (A) Buildup Runs x 2-3 x 20-30m
A33: 8LwicVSASJqsKlgnaXaQJA | B33: WU C | D33: General | E33: Warm-Up | H33: Jog-skip 400m Static Stretch (prescribed) Sprint Drills (A) x 1 x 20m Dynamic Flexibility (A) Buildup Runs x 2-3 x 20-40m
A35: wZ7mIs5NTwWCjSU9fDeKyw | B35: Drills A | D35: General | E35: Sprint Drills
A36: qMNd06PsRA2TxUn69zbGDQ | B36: Drills B | D36: General | E36: Sprint Drills
A38: lx3Jhw48TSyptWnmJQ5JSw | B38: Series A | D38: General | E38: Dynamic Flexibility
A39: UWzOzBAaQbuhhCulyhbMqQ | B39: Series B | D39: General | E39: Dynamic Flexibility
A41: YVCGl86qSWSR1zv4y2GyCw | B41: Mobility Series A | D41: General | E41: Hurdle Mobility | H41: Spacing: Rail-to-Rail or 1 foot
A42: lDpd.yt3QL2mNfItz9BzHQ | B42: Mobility Series B | D42: General | E42: Hurdle Mobility | H42: Spacing: 1 foot for first two, 3 feet for remaining
A44: VwSYL5VhQpG7g-8Pv0Q.pg | B44: Agility Series | D44: General | E44: General Agility
A46: TJnlSymoTuSIICIGHPFjkA | B46: 1. Acceleration | D46: General | E46: Ancillary Bike | H46: 15-25 Bouts of 10 seconds at very high wheel resistance | I46: 1' rest within each set, 3-5' rest between sets
A47: tF9wCxWXS-2HZwiIjqrpNA | B47: 2. Speed Development | D47: General | E47: Ancillary Bike | H47: 10-15 Bouts of 20-30 seconds at high resistance | I47: 2-3' rest within each set, 5' rest between sets
A48: DGyTHglxR.e3RdgtOrWK8A | B48: 3. Special Speed Endurance | D48: General | E48: Ancillary Bike | H48: 8-10 Bouts of 45-60 seconds at medium to high resistance | I48: Varies depending on goal (30 seconds - 5 minutes)
A50: Kw-Xoi-FS8elN9QPnw9ivA | B50: Medball Striking Progression | D50: Circuits | E50: Overhead Striking
A52: bGtfpnF-Q1qF7uCVpYbU4g | B52: Set A | D52: Mobility | E52: Static Flexibility

Sheet Items
A1: Item | B1: Image | C1: Instructions | D1: Details | E1: Circuit 1 | F1: Circuit 2 | G1: Circuit 3 | H1: Circuit 4 | I1: Circuit 5 | J1: Circuit 6 | K1: Circuit 7 | L1: Circuit 8 | M1: Circuit 9 | N1: Circuit 10 | O1: Circuit 11 | P1: Circuit 12 | Q1: Circuit 13 | R1: Circuit 14 | S1: Circuit 15 | T1: Circuit 16 | U1: Circuit 17 | V1: Circuit 18 | W1: Circuit 19 | X1: Circuit 20 | Y1: Circuit 21 | Z1: Circuit 22 | AA1: Circuit 23 | AB1: Circuit 24 | AC1: Circuit 25 | AD1: Circuit 26 | AE1: Circuit 27 | AF1: Circuit 28 | AG1: Circuit 29 | AH1: Circuit 30 | AI1: Circuit 31 | AJ1: Circuit 32 | AK1: Circuit 33 | AL1: Circuit 34 | AM1: Circuit 35 | AN1: Circuit 36 | AO1: Circuit 37 | AP1: Circuit 38 | AQ1: Circuit 39 | AR1: Circuit 40 | AS1: Circuit 41 | AT1: Circuit 42 | AU1: Circuit 43 | AV1: Circuit 44 | AW1: Circuit 45 | AX1: Circuit 46 | AY1: Circuit 47 | AZ1: Circuit 48 | BA1: Circuit 49 | BB1: Circuit 50 | BC1: Circuit 51 | BD1: Circuit 52 | BE1: Circuit 53 | BF1: Circuit 54 | BG1: Circuit 55 | BH1: Primary Cue
A2: Prisoner Squats | B2: https://storage.googleapis.com/glide-prod.appspot.com/uploads-v2/cMkSU7tNCGrXdOICNUYw/pub/ghiHDDiM7cJZKIQ7i4TP.gif | C2: Standing with hands behind your head, squat with heels pressed into ground to 90° and back up. | E2: Waterloo
A3: V-Situps | B3: https://storage.googleapis.com/glide-prod.appspot.com/uploads-v2/cMkSU7tNCGrXdOICNUYw/pub/Ir9Vaq5DCPbYkubRmP30.gif | C3: Make sure to keep arms and legs long, bringing arms overhead as you go down. | E3: Waterloo
A4: Push-ups | B4: https://storage.googleapis.com/glide-prod.appspot.com/uploads-v2/cMkSU7tNCGrXdOICNUYw/pub/a7SclcnJxTRdR7pE1zJt.gif | E4: Waterloo
A5: Back Hypers w/Twist | B5: https://storage.googleapis.com/glide-prod.appspot.com/uploads-v2/cMkSU7tNCGrXdOICNUYw/pub/PeUb9fjIy69bD4yaeep7.gif | E5: Waterloo
A6: Rocket Jumps | B6: https://storage.googleapis.com/glide-prod.appspot.com/uploads-v2/cMkSU7tNCGrXdOICNUYw/pub/wGmVP9tyNpZd75WKdOrB.gif | E6: Waterloo
A7: Leg Toss | B7: https://storage.googleapis.com/glide-prod.appspot.com/uploads-v2/gtfdDGd9EKORi4XOZq7P/pub/P1gucdHG63YeGcLgAxij.gif | E7: Waterloo
A8: Push-ups with Clap | B8: https://storage.googleapis.com/glide-prod.appspot.com/uploads-v2/cMkSU7tNCGrXdOICNUYw/pub/WsPgSPZONmBjfJXXwDPM.gif | E8: Waterloo
A9: Wrestler’s Bridge | B9: https://storage.googleapis.com/glide-prod.appspot.com/uploads-v2/cMkSU7tNCGrXdOICNUYw/pub/jhkF8JMdcCd3H7Gzh7nN.gif | E9: Waterloo
A10: Crunch Sit-ups | B10: https://storage.googleapis.com/glide-prod.appspot.com/uploads-v2/gtfdDGd9EKORi4XOZq7P/pub/lq52vmieHugC3cNtxsth.gif | E10: Waterloo
A11: Navy Seal Push-ups | B11: https://storage.googleapis.com/glide-prod.appspot.com/uploads-v2/cMkSU7tNCGrXdOICNUYw/pub/3OKUaFPS10QhlUpvqMVs.gif | E11: Waterloo
A12: Prone Single-leg Hip Extensions | B12: https://storage.googleapis.com/glide-prod.appspot.com/uploads-v2/cMkSU7tNCGrXdOICNUYw/pub/JGnhZuV4hJaLyaj1Agy8.gif | E12: Waterloo
A14: Single Leg Squats | B14: https://storage.googleapis.com/glide-prod.appspot.com/uploads-v2/cMkSU7tNCGrXdOICNUYw/pub/a5ybUJQs1AdH5WDp7MWU.gif | C14: Squat on one leg | F14: Bataan
A15: Toe Touchers | B15: https://storage.googleapis.com/glide-prod.appspot.com/uploads-v2/cMkSU7tNCGrXdOICNUYw/pub/hmPoo1pgS8iZUjoZBPDb.gif | F15: Bataan
A16: Push-ups | B16: https://storage.googleapis.com/glide-prod.appspot.com/uploads-v2/cMkSU7tNCGrXdOICNUYw/pub/8OyagjuowaFEWjZemvWu.gif | F16: Bataan
A17: Back Hypers | B17: https://storage.googleapis.com/glide-prod.appspot.com/uploads-v2/cMkSU7tNCGrXdOICNUYw/pub/cJIauV3TJDqG5ilER0zo.gif | F17: Bataan
A18: Yogi Hamstring Leans | B18: https://storage.googleapis.com/glide-prod.appspot.com/uploads-v2/cMkSU7tNCGrXdOICNUYw/pub/b32ASK1xu2vYRHuVRNj1.gif | F18: Bataan
A19: Side-ups | B19: https://storage.googleapis.com/glide-prod.appspot.com/uploads-v2/cMkSU7tNCGrXdOICNUYw/pub/SPISuEOuwLfRGd91VNfW.gif | F19: Bataan
A20: Lunge Good Mornings | B20: https://storage.googleapis.com/glide-prod.appspot.com/uploads-v2/cMkSU7tNCGrXdOICNUYw/pub/X9dQRfCJR13vNFhamjqc.gif | F20: Bataan
A21: Push-ups with Clap | B21: https://storage.googleapis.com/glide-prod.appspot.com/uploads-v2/cMkSU7tNCGrXdOICNUYw/pub/ky8SwIUeA02g3phijvgQ.gif | F21: Bataan
A22: Push-up Toe Walks | F22: Bataan
A23: Prone Flexed-knee Hip Extension | B23: https://storage.googleapis.com/glide-prod.appspot.com/uploads-v2/gtfdDGd9EKORi4XOZq7P/pub/gUkw5yEYyJQ8UX3yiCRr.gif | F23: Bataan
A24: Double Leg Eagles | B24: https://storage.googleapis.com/glide-prod.appspot.com/uploads-v2/gtfdDGd9EKORi4XOZq7P/pub/gx4RUqCo0VtGrggfi5vC.gif | F24: Bataan
A26: V-Situps | B26: https://storage.googleapis.com/glide-prod.appspot.com/uploads-v2/cMkSU7tNCGrXdOICNUYw/pub/bfTo2xSFPDJNuPrdpPL7.gif | G26: Pillar
A27: Back Hypers | B27: https://storage.googleapis.com/glide-prod.appspot.com/uploads-v2/cMkSU7tNCGrXdOICNUYw/pub/X59KMLV2csQJ1O52gSq1.gif | G27: Pillar
A28: Leg Toss | B28: https://storage.googleapis.com/glide-prod.appspot.com/uploads-v2/cMkSU7tNCGrXdOICNUYw/pub/JMnOkOBSdPFb9YjdhhD6.gif | G28: Pillar
A29: Wrestler’s Bridge | B29: https://storage.googleapis.com/glide-prod.appspot.com/uploads-v2/cMkSU7tNCGrXdOICNUYw/pub/Gh5Ah14xonI6gRgefy3Y.gif | G29: Pillar
A30: Crunch w/Twist | B30: https://storage.googleapis.com/glide-prod.appspot.com/uploads-v2/cMkSU7tNCGrXdOICNUYw/pub/RryukIonEOvSP8jZEN3A.gif | G30: Pillar
A31: Prone Flexed-knee Hip Extension | B31: https://storage.googleapis.com/glide-prod.appspot.com/uploads-v2/gtfdDGd9EKORi4XOZq7P/pub/gUkw5yEYyJQ8UX3yiCRr.gif | G31: Pillar
A32: Toe Touchers | B32: https://storage.googleapis.com/glide-prod.appspot.com/uploads-v2/cMkSU7tNCGrXdOICNUYw/pub/tGwQz6LBxNt3GvyzINRA.gif | G32: Pillar
A33: L-Overs | B33: https://storage.googleapis.com/glide-prod.appspot.com/uploads-v2/cMkSU7tNCGrXdOICNUYw/pub/Aeqlx3yBPQzOsfbcC89c.gif | G33: Pillar
A34: Side-ups | B34: https://storage.googleapis.com/glide-prod.appspot.com/uploads-v2/cMkSU7tNCGrXdOICNUYw/pub/IdSUP0g0goG25upymUwL.gif | G34: Pillar
A35: Double Leg Eagles | B35: https://storage.googleapis.com/glide-prod.appspot.com/uploads-v2/gtfdDGd9EKORi4XOZq7P/pub/gx4RUqCo0VtGrggfi5vC.gif | G35: Pillar
A36: Low-level Bicycle | G36: Pillar
A37: Pelvic Tilt Isometrics | G37: Pillar
A38: Pelvic Tilt w/ Leg Crunch | G38: Pillar
A40: Standing Overhead Forward | B40: https://storage.googleapis.com/glide-prod.appspot.com/uploads-v2/cMkSU7tNCGrXdOICNUYw/pub/hoem5JzJYzzwIhiY8h9l.gif | H40: Gas
A41: Hip Catch & Toss | B41: https://storage.googleapis.com/glide-prod.appspot.com/uploads-v2/cMkSU7tNCGrXdOICNUYw/pub/ACfY37j3h6EWId8jQmKz.gif | H41: Gas
A42: MB Good Morning | B42: https://storage.googleapis.com/glide-prod.appspot.com/uploads-v2/cMkSU7tNCGrXdOICNUYw/pub/jBIfHuV4RApauQZ1G6M0.gif | H42: Gas
A43: MB V-Ups | B43: https://storage.googleapis.com/glide-prod.appspot.com/uploads-v2/cMkSU7tNCGrXdOICNUYw/pub/Jd9GQP9Hzua8WMiVM4S4.gif | H43: Gas
...

Sheet Password
A1: 🔒 Row ID

Sheet Profiles
A1: 🔒 Row ID | B1: Email | C1: Name | D1: Hometown | E1: Season Goal | F1: Weekly Goals | G1: Profile Pic | H1: Profile? | I1: TJ? | J1: Workout Image | K1: Free Access? | L1: Password
A2: lCH93zyfSRu9vF-nQ6uiFA | B2: curtisbeach12@gmail.com | C2: Curtis Beach | E2: 8000+ | G2: https://storage.googleapis.com/glide-prod.appspot.com/uploads-v2/gtfdDGd9EKORi4XOZq7P/pub/WNN9C8Hn1h525hepPlSv.jpg | H2: FALSE | I2: FALSE
A3: WvU0Ib5dRpm-9Lw-qOE4Tg | B3: meengis@gmail.com | C3: AJ Beach | D3: Albuquerque, NM | E3: Season Goal | H3: FALSE
A4: IzrQLwB1QxOYWmxNWMj2xA | B4: jellis186@gmail.com | C4: Jade | H4: TRUE
A5: Mc6ZeyXFQ7y7E90fRT5fhQ | B5: shawn.wilbourn@duke.edu | H5: FALSE
A6: XUE1fYFDQxK7rK8wXnQI7w | B6: sposwald88@gmail.com
A7: BA67m7IGS8-UKfMvJ0VxEw | B7: mbm52@duke.edu
A8: MRrtUejoQg-psXk1zScThQ | B8: alexandraeapple@gmail.com | H8: FALSE | I8: FALSE
A9: hGMt2weaSpOqgdPXm2ucMA | B9: dreamngold@gmail.com | H9: TRUE | K9: TRUE
A10: a1DOp.n7SlO0KPSCtnGR2Q | B10: ranna320@gmail.com
A11: FjkGFkxzQnmEyeg5WiisKA | B11: arnie.garza@gmail.com | C11: Arnie Garza | E11: 7000 | F11: 2 session of accelerations 1 x tempo 1 speed | L11: Athletics
A12: ZOyhDXPCRR-.HiOGtBpRvg | B12: karenyaa@hotmail.com
A13: eIKOmEz-SJ2gkWbsXnOdUA | B13: lvgatletika@shaw.ca
A14: DTya9ernT.O1gDuqmzagBA | B14: ed.fye@doane.edu | K14: TRUE
A15: KrWJnFyWQ0SR9q5-tPFYSQ | B15: curtis.beach12@gmail.com
A16: iFrkngXfQm-6KTxL.xhgJA | B16: alpha.kamara89@yahoo.com
A17: RpG8R2WNSVqXEu9pE6AuLg | B17: hfwilliams@icloud.com | K17: TRUE | L17: Athletics
A18: AXhYuBcXTcu2zfRLu7eIjQ | B18: meskind@gmail.com
A19: 2NBWEtvzQH25VFtHU5Dvmg | B19: ethanalan@rocketmail.com
A20: a-1SfCBoeTja8DvYoJUgiiA | B20: archiwyatt@gmail.com | C20: Matt Wyatt | E20: 7.80 | L20: Athletics
A21: TYWdMNHFTLqIzOyXu0sfIQ | B21: alexar@alumni.stanford.edu
A22: 06xmoOShRv69cTrsYv8J-g | B22: manaalison@gmail.com | L22: Athletics
A23: jREDkZUATAGeOqlPFiJJyg | B23: hoseabjr1@gmail.com
A24: awM2uWpIQVe871dxdH3E.g | B24: harris.helberg@bellsouth.net | G24: https://storage.googleapis.com/glide-prod.appspot.com/uploads-v2/gtfdDGd9EKORi4XOZq7P/pub/vFwqBrfueaFMvL4NJUae.jpeg | L24: Athletics
A25: OaticxiZTlGTpaqEJuZAKQ | B25: harris.helberg@bellsouth.net
A26: 3sVZnlutSluv01Atm7CNaQ | B26: aaron.j.booth@live.com | L26: Athletics
A27: 75eJMF4USIKQdJPd-bAUaw | B27: vigiljonahbucs@yahoo.com
A28: La39FLYWRvmbk7zo3iJEkA | B28: nfan1310@gmail.com
A29: SY1mQ7TxSnO3DeELNCyTJw | B29: rosskortney@gmail.com
A30: 5sx9OdrbRP64oyrosaAODg | B30: decmasterson@gmail.com | G30: https://storage.googleapis.com/glide-prod.appspot.com/uploads-v2/gtfdDGd9EKORi4XOZq7P/pub/Wa5NU9EcqKuhoOP5LRRj.jpeg
A31: 6x8mh1wFSFOIDPRSFaFLTw | B31: henrikjfholmberg@gmail.com
A32: VxgVwQaiQb2iU3P9bqeZxQ | B32: robertrohner13@gmail.com
A33: WtCsIlYkTVaKPZVxc4cFsg | B33: mariowilson1010@gmail.com
A34: CWm31-fLQ1qlc5jOM.WZ0A | B34: datesta@gmail.com
A35: D7stRmpLSyScuZ3F1rDA6g | B35: rvdavis@aol.com
A36: Z04bAUFJQN-YFakJKnr5bA | B36: ryan.dorshorst@doane.edu | K36: FALSE
A37: MZxif7CpRmq6KLej3PXMpQ | B37: curtisbeach.12@gmail.com
A38: E3r2fNqyQxGDmvv61UckQQ | B38: grace.damme@doane.edu
A39: A4ENxr98TxuQpGIMPERjxA | B39: madison.blackstone@doane.edu
A40: Fcf1Ojv6Se--vgX9MtRQkw | B40: isabelle.watson@doane.edu
...

Sheet Subscribers
A1: User | B1: Pro Active
A2: =Profiles!B2 -> curtisbeach12@gmail.com | B2: =IFERROR(VLOOKUP(Profiles!B2,'App Sales'!B:B,1,FALSE)," ") -> curtisbeach12@gmail.com
A3: =Profiles!B3 -> meengis@gmail.com | B3: =IFERROR(VLOOKUP(Profiles!B3,'App Sales'!B:B,1,FALSE)," ") -> meengis@gmail.com
A4: =Profiles!B4 -> jellis186@gmail.com | B4: =IFERROR(VLOOKUP(Profiles!B4,'App Sales'!B:B,1,FALSE)," ")
A5: =Profiles!B5 -> shawn.wilbourn@duke.edu | B5: =IFERROR(VLOOKUP(Profiles!B5,'App Sales'!B:B,1,FALSE)," ")
A6: =Profiles!B6 -> sposwald88@gmail.com | B6: =IFERROR(VLOOKUP(Profiles!B6,'App Sales'!B:B,1,FALSE)," ") -> sposwald88@gmail.com
A7: =Profiles!B7 -> mbm52@duke.edu | B7: =IFERROR(VLOOKUP(Profiles!B7,'App Sales'!B:B,1,FALSE)," ")
A8: =Profiles!B8 -> alexandraeapple@gmail.com | B8: =IFERROR(VLOOKUP(Profiles!B8,'App Sales'!B:B,1,FALSE)," ")
A9: =Profiles!B9 -> dreamngold@gmail.com | B9: =IFERROR(VLOOKUP(Profiles!B9,'App Sales'!B:B,1,FALSE)," ") -> dreamngold@gmail.com
A10: =Profiles!B10 -> ranna320@gmail.com | B10: =IFERROR(VLOOKUP(Profiles!B10,'App Sales'!B:B,1,FALSE)," ")
A11: =Profiles!B11 -> arnie.garza@gmail.com | B11: =IFERROR(VLOOKUP(Profiles!B11,'App Sales'!B:B,1,FALSE)," ")
A12: =Profiles!B12 -> karenyaa@hotmail.com | B12: =IFERROR(VLOOKUP(Profiles!B12,'App Sales'!B:B,1,FALSE)," ")
A13: =Profiles!B13 -> lvgatletika@shaw.ca | B13: =IFERROR(VLOOKUP(Profiles!B13,'App Sales'!B:B,1,FALSE)," ")
... A979: =Profiles!B979 -> 0 | B979: =IFERROR(VLOOKUP(Profiles!B979,'App Sales'!B:B,1,FALSE)," ")

Sheet Payment
A1: Product ID | B1: Name | C1: Description | D1: Image | E1: Price | F1: Log-In | G1: 🔒 Row ID | H1: Details | I1: Comparison
A2: 1 | B2: Individual | C2: Does not auto-renew. Use the email you logged in with to gain access. | D2: https://storage.googleapis.com/glide-prod.appspot.com/uploads-v2/gtfdDGd9EKORi4XOZq7P/pub/kwp5gurPeuiLqZOVURU6.jpg | E2: 29 | F2: After buying, sign in with the same email you use for "Contact Information" below. | G2: yUR440zKSKuxaYZuZIzEyQ | H2: One-time purchase | I2: https://storage.googleapis.com/glide-prod.appspot.com/uploads-v2/gtfdDGd9EKORi4XOZq7P/pub/HGTsbAOV0hgsoWLVTdJ3.png
A3: 2 | B3: Team | C3: Does not auto-renew. Use the email you logged in with to gain access. | D3: https://storage.googleapis.com/glide-prod.appspot.com/uploads-v2/gtfdDGd9EKORi4XOZq7P/pub/3DOrFedQfckjp8rPjByW.jpg | E3: 79 | F3: Email Curtis (curtisbeach12@gmail.com) with the emails of the athletes you wish to activate this for. | G3: 76Xt.kr9Qj2H6LRr5awiVA | H3: For 10 athletes
A4: 3 | B4: Test | D4: https://storage.googleapis.com/glide-prod.appspot.com/uploads-v2/gtfdDGd9EKORi4XOZq7P/pub/SGGnyAjcDAo2ZVcoNVw5.jpg | E4: 0.5 | F4: After buying, sign in with the same email you use for "Contact Information" below. | G4: Hq8AtZkxQ1a-NIQjhv13nA
A5: 4 | B5: Discount | D5: https://storage.googleapis.com/glide-prod.appspot.com/uploads-v2/gtfdDGd9EKORi4XOZq7P/pub/IducvViSnd5NyYJZG4vK.jpg | E5: 9 | F5: After buying, sign in with the same email you use for "Contact Information" below. | G5: dBvqtXZcR1muvajhXrqpYA | H5: One-time purchase

Sheet Workouts
A1: Event Group | B1: Macro | C1: Duration | D1: Meso Image | E1: Description
A2: Combined Events | B2: Off Season
A3: Combined Events | B3: Off Season
A4: Combined Events | B4: Off Season
A5: Combined Events | B5: Off Season
A6: Combined Events | B6: Early Season
A7: Combined Events | B7: Early Season
A8: Combined Events | B8: Early Season
A9: Combined Events | B9: Early Season
A10: Combined Events | B10: Mid Season
A11: Combined Events | B11: Mid Season
A12: Combined Events | B12: 4-Day Rollover

Sheet Macrocycles
A1: Event Group | B1: Macrocycle | C1: Duration | D1: Mesocycle Uno | E1: Mesocycle Dos | F1: Mesocycle Tres | G1: Mesocycle Cuatro | H1: Phase 1 | I1: Phase 2 | J1: Phase 3 | K1: Phase 4 | L1: Description | M1: About | N1: Rollover Uno | O1: Rollover Dos | P1: Extra Text
A2: Combined Events | B2: Off Season | C2: 12 Weeks | D2: https://storage.googleapis.com/glide-prod.appspot.com/uploads-v2/gtfdDGd9EKORi4XOZq7P/pub/OoJSRTSaBooDF4kru6Y7.pdf | E2: https://storage.googleapis.com/glide-prod.appspot.com/uploads-v2/gtfdDGd9EKORi4XOZq7P/pub/z2Xnh2tS3ZTc3DNd5Ju2.pdf | F2: https://storage.googleapis.com/glide-prod.appspot.com/uploads-v2/gtfdDGd9EKORi4XOZq7P/pub/iiZODEWnGdvOE280zMB9.pdf | G2: https://storage.googleapis.com/glide-prod.appspot.com/uploads-v2/gtfdDGd9EKORi4XOZq7P/pub/I6TpYHu8n13NFub75wm9.pdf | H2: Phase I | I2: Phase II | J2: Phase III | K2: Phase IV | L2: Phase I | M2: Each Phase is three weeks. Take the last week as a lighter unload week.
A3: Combined Events | B3: Early Season | C3: 12 Weeks | D3: https://storage.googleapis.com/glide-prod.appspot.com/uploads-v2/gtfdDGd9EKORi4XOZq7P/pub/1ecRCcZJOvpanJpgaxV0.pdf | E3: https://storage.googleapis.com/glide-prod.appspot.com/uploads-v2/gtfdDGd9EKORi4XOZq7P/pub/ORNz0qJXkvFFXya0X6gG.pdf | F3: https://storage.googleapis.com/glide-prod.appspot.com/uploads-v2/gtfdDGd9EKORi4XOZq7P/pub/MW3Zs8gIcnxh2LpxngMi.pdf | G3: https://storage.googleapis.com/glide-prod.appspot.com/uploads-v2/gtfdDGd9EKORi4XOZq7P/pub/XE2QkinT4KcDOxkNZ5ox.pdf | H3: Phase I | I3: Phase II | J3: Phase III | K3: Phase IV | L3: Phase II | M3: Each Phase is three weeks. Take the last week as a lighter unload week.
A4: Combined Events | B4: Mid Season | C4: 6 Weeks | D4: https://storage.googleapis.com/glide-prod.appspot.com/uploads-v2/gtfdDGd9EKORi4XOZq7P/pub/3bcBcxJkCmNM1ABIWJrk.pdf | E4: https://storage.googleapis.com/glide-prod.appspot.com/uploads-v2/gtfdDGd9EKORi4XOZq7P/pub/LDH3yswAcMSv3X8t3rNm.pdf | H4: Phase I | I4: Phase II | J4: Phase III | K4: Phase IV | L4: Phase III | M4: Each Phase is three weeks. Take the last week as a lighter unload week.
A5: Combined Events | B5: Competition Rollover | C5: Variable Duration | H5: Phase I | I5: Phase II | J5: Phase III | K5: Phase IV | L5: Phase IV | N5: https://storage.googleapis.com/glide-prod.appspot.com/uploads-v2/gtfdDGd9EKORi4XOZq7P/pub/wTxGlwdY5Cl2jMzfccWO.pdf | O5: https://storage.googleapis.com/glide-prod.appspot.com/uploads-v2/gtfdDGd9EKORi4XOZq7P/pub/kcF7hPWYO4UFIytoh7oF.pdf | P5: 1. % on weight training is to be stimulating but not risky. Try to hit one hard lift session at least once every 10-12 days. 2. Normal pre-meet schemes will be used on the day before the meet and the day of the meet. 3. Try to do a warmup A at least once every ten days. 4. You should cycle the day 2, 3 and 4 runs each time through. 5. One fartlek every 8-10 days: 15-20 minutes of 1on-2off.

Sheet Mesocycles
A1: Mesocycle | B1: Day 1 | C1: Day 2 | D1: Day 3 | E1: Day 4 | F1: Day 5 | G1: Day 6 | H1: Day 7
A2: Phase I | B2: Monday | C2: Tuesday | D2: Wednesday | E2: Thursday | F2: Friday | G2: Saturday | H2: Sunday
A3: Phase II | B3: Monday | C3: Tuesday | D3: Wednesday | E3: Thursday | F3: Friday | G3: Saturday | H3: Sunday
A4: Phase III | B4: Monday | C4: Tuesday | D4: Wednesday | E4: Thursday | F4: Friday | G4: Saturday | H4: Sunday
A5: Phase IV | B5: Monday | C5: Tuesday | D5: Wednesday | E5: Thursday | F5: Friday | G5: Saturday | H5: Sunday

Sheet Microcycles
A1: 🔒 Row ID | B1: Title Image | C1: Cycle | D1: Macrocycle | E1: Mesocycle Phase | F1: Phase 1 | G1: Phase 2 | H1: Phase 3 | I1: Phase 4 | J1: Day | K1: Purpose | L1: Type | M1: Notes | N1: First | O1: Second | P1: Third | Q1: Fourth | R1: Fifth | S1: Sixth | T1: Seventh | U1: Eighth
A2: ysSt8A0OQBC8iM8OlHTOHg | B2: https://storage.googleapis.com/glide-prod.appspot.com/uploads-v2/cMkSU7tNCGrXdOICNUYw/pub/qaD9GA0o2iitR31yOowr.png | C2: Rollover | D2: Competition Rollover | E2: Rollover | J2: Day 1 | L2: Acceleration | N2: 1. **Warm Up A or B** | O2: 2. **Workout** 2-3 x 30,40,50m R = 3' and 8' Over hurdles optional | P2: 3. **Throw Tech** Discus or Javelin | Q2: 4. **Multi Jump** (choose one) a) Rudiment 1x15-30m b) RIP x3 c) 5x3 Hurdle Hops | R2: 5. **Weights** a) Olympics: 8 x 1, can use hang, full or one arm b) Press or Pullovers: 3x2; 3x1 c) Low Box Stepups: 6x3 or Hex Bar Deadlift 6 x 4 d) Russian Twists: OH Standing: 3x10 e) Negative Toe Risers: 3 x 10 | S2: 6. **Cool Down** 5' bike mixed or easy job skip
A3: 6tR84TAUQLOb2ggLqza-PA | B3: https://storage.googleapis.com/glide-prod.appspot.com/uploads-v2/cMkSU7tNCGrXdOICNUYw/pub/c4vp4vVZ9GsHy1mXq5us.png | C3: Rollover | D3: Competition Rollover | E3: Rollover | J3: Day 2 | L3: Jumps | N3: 1. **Warm Up B** | O3: 2. **Jump Session** | P3: 3. **Speed Development** (choose one) a) 3-4 x 40-90m (R=8’), over hurdles optional b) 3 x 120 or 150 (R=10’) | Q3: 4. **Throw Tech** Shot Put | R3: 5. **General Strength** 1 x 10 Pillar and/ or Pedestal on even weeks 1 x 10 Bataan and/ or Waterloo on odd weeks | S3: 6. **Medicine Ball** 1 x 10 Gas on even weeks 1 x 10 Tank on odd weeks | T3: 7. **Cool Down** 3-5’ bike or easy jogging | U3: *Emphasis on hydrotherapy recovery techniques*
A4: CCo8OW8JRFSkLo850ygDhQ | B4: https://storage.googleapis.com/glide-prod.appspot.com/uploads-v2/cMkSU7tNCGrXdOICNUYw/pub/DvJTJdF7PWPQYQrb16gb.png | C4: Rollover | D4: Competition Rollover | E4: Rollover | J4: Day 3 | L4: Speed Endurance | N4: 1. **Warm Up B or C** | O4: 2. **Throw Tech** Javelin | P4: 3. **Special Speed Endurance** (choose one) a) 300,200,150 w/ R 10-15’ b) 350, 250, 200 w/ R 8-12’ c) 180, 150, 120 w/ R 10-12’ | Q4: 4. **Multi Throw** (choose one) a) Grenade x3 b) Bomb x3 | R4: 5. **Weights** a) Olympics: 4 x 1 full; 4x1 hang b) Box Positives: 8 x 3 c) Russian Twists: Seated, Pause/Explode: 3 x 10 d) Positive Toe Risers: 3 x 10 | S4: 5. **Cool Down** 5’ bike easy or jog/skip
A5: HkRNaRvaThiiAvw-H0T-6w | B5: https://storage.googleapis.com/glide-prod.appspot.com/uploads-v2/cMkSU7tNCGrXdOICNUYw/pub/muLrzzkdeIrbwo8T90CR.png | C5: Rollover | D5: Competition Rollover | E5: Rollover | J5: Day 4 | L5: Jumps / Endurance | N5: 1. **Warm Up B** | O5: 2. **Jump Session** | P5: 3. **Throw Tech** Choice | Q5: 4. **Tempo Endurance Runs** (choose one) a) 3x 500 or 600 w/2-3’ R b) 2 x 700m w/ 2-3’ R c) 1000, 800, 600 w/ 3’ and 4’ R | R5: 5. **Cool Down** 5' easy jog/skip
A6: f7BtA-WRRX2bTKYxnFNVnw | C6: Cycle 1.1 | D6: Off Season | E6: Phase I | F6: Monday | J6: Monday | K6: System Introduction | N6: 1. **Warm Up A** | O6: 2. **Acceleration Dev** 4 x 10,20,30m ladder; (rollover start) R = 1' & 2-3' | P6: 3. **Multiple Jump** 3-5x RIP or 5x5H Hops (Freeze) | Q6: 4. **Weight Train** Olympic Lift--TBA--6 x 2 full; 6 x 2 hang @ (80-85% PEI) Press--TBA--4 x 4; 2 x 3; 2 x 2 (progressive loads) Low Box Stepups--6 x 4 @ (80% PEI) **box=10-20cm Lunge Russian Twists x 3 x 20m w/ 10-20k plate Russian Twists-- 3 x 10 ( Seated Low Reach) Negative Toe Risers--3 x 10 (moderate load) **negative axis only | R6: 5. **Cool Down** Jog, Skip, Side Shuffle or Easy Bike
A7: GavdhT2GT460TLRJs9bqLg | C7: Cycle 1.1 | D7: Off Season | E7: Phase I | F7: Tuesday | J7: Tuesday | K7: System Introduction | N7: 1. **Warm Up B** | O7: 2. **Jump Prep** Trek: 2x30-40m | P7: 3. **General Strength** Pedestal, then Pillar | Q7: 4. **Multiple Throw** Gas | R7: 5. **Weight Train** | S7: 6. **Cool Down** 5' bike, mixed speed
A8: 37YSuxeiRSeJ0SHzZ5zAxQ | C8: Cycle 1.1 | D8: Off Season | E8: Phase I | F8: Wednesday | J8: Wednesday | K8: System Introduction | N8: 1. **Warm Up B** | O8: 2. **Sprint Tech Dev** 4-6 60-80m Up-Backs R=3' | P8: 3. **Multiple Jump** Everest and/or Kilimanjaro x20" | Q8: 4. **Weight Train** | R8: 5. **Cool Down** Easy jog or bike
A9: f6Szoz2XQAufTx0UTep.GA | C9: Cycle 1.1 | D9: Off Season | E9: Phase I | F9: Thursday | J9: Thursday | K9: System Introduction | N9: 1. **Warm Up A** | O9: 2. **Jump Prep** Rudiment 2x30m | P9: 3. **General Strength** Bataan, then Waterloo | Q9: 4. **Multiple Throw** Tank | R9: 5. **Hurdle Mobility** 5x5H Series 1-4 | S9: 6. **Weight Train** | T9: 7. **Cool Down** 5' Bike or Jog
A10: 6BDWL9cEQJ61XNbNmZmK.A | C10: Cycle 1.1 | D10: Off Season | E10: Phase I | F10: Friday | J10: Friday | K10: System Introduction | N10: 1. **Warm Up B** | O10: 2. **Acceleration Dev** 4 sets of 3x20m (rollover start) with hills or light sled R=1'-2' | P10: 3. **Multiple Throw** Bomb x5 | Q10: 4. **Weight Train** | R10: 5. **Cool Down** Jog/Skip or Mixed-speed bike
A11: aKLcaZ77T4ONeE7kTGvrhg | C11: Cycle 1.1 | D11: Off Season | E11: Phase I | F11: Saturday | J11: Saturday | K11: System Introduction | N11: 1. **Warm Up B** | O11: 2. **Special Endurance** 2 sets of 6x90m; or 2 sets of 5x120; or 2 sets of 4x150 R= 2' & 5' | P11: 3. **Multiple Jump** 10x 5H Low Hops | Q11: 4. **Hurdle Mobility** 3x 5H Series 1-4 | R11: 5. **Weight Train** | S11: 6. **Cool Down** 5' Bike
A12: cpc6nNYgSyKd-.rpTVQuHA | C12: Cycle 1.1 | D12: Off Season | E12: Phase I | F12: Sunday | J12: Sunday | K12: System Introduction | N12: Active Rest or Complete Rest
A13: gn.hnbSTRP65dGa-Skfe7w | C13: Cycle 1.2 | D13: Off Season | E13: Phase II | G13: Monday | J13: Monday | K13: Technical Introducation | N13: 1. **Warm Up A** | O13: 2. **Acceleration Dev** 4-5 sets of 3x30m; (rollover start). Can use hurdles w/ low & close spacings R = 2-3' | P13: 3. **Multiple Jump** 3x RIP or 5x5H Hops (Freeze) | Q13: 4. **Weight Train** | R13: 5. **Cool Down** Jog, Skip, Side Shuffle
A14: lCWEBXS-T.28OzXNcV9R.g | C14: Cycle 1.2 | D14: Off Season | E14: Phase II | G14: Tuesday | J14: Tuesday | K14: Technical Introducation | N14: 1. **Warm Up B** | O14: 2. **Jump Tech** Or Sprint Tech: 6-8 x 50-70m dribble (height tba) R = 3' - 5' | P14: 3. **General Strength** Pedestal, then Pillar | Q14: 4. **Multiple Throw** Gas | R14: 5. **Weight Train** | S14: 6. **Cool Down** 5' bike, mixed speed
A15: VlGWZs8IR2eyaNw.YZuggQ | C15: Cycle 1.2 | D15: Off Season | E15: Phase II | G15: Wednesday | J15: Wednesday | K15: Technical Introducation | N15: 1. **Warm Up B** | O15: 2. **Special Endurance Intro** Ladder Runs x 4 (e.g. 6,5,4,3) R=2' | P15: 3. **Multiple Throw** Grenade x3 w/ 4-5k SP | Q15: 4. **Weight Train** | R15: 5. **Cool Down** Easy jog or bike
A16: rapr6ZuOTLigI378stfxDA | C16: Cycle 1.2 | D16: Off Season | E16: Phase II | G16: Thursday | J16: Thursday | K16: Technical Introducation | N16: 1. **Warm Up A** | O16: 2. **Jump Tech / Endurance Plyos** Trek 2x20-30m | P16: 3. **General Strength** Bataan, then Waterloo | Q16: 4. **Multiple Throw** Tank | R16: 5. **Hurdle Mobility** 5x5H Series 1-4 | S16: 6. **Weight Train** | T16: 7. **Cool Down** Bike or Jog
A17: fRuFq7vYQOuEnR7m6jQGFg | C17: Cycle 1.2 | D17: Off Season | E17: Phase II | G17: Friday | J17: Friday | K17: Technical Introducation | N17: 1. **Warm Up B** | O17: 2. **Jump Tech** | P17: 3. **Multiple Throw** Bomb x3 | Q17: 4. **Weight Train** | R17: 5. **Cool Down** Jog/Skip or Mixed-speed bike
A18: NeVqZkklT-GTflWnHGAQzw | C18: Cycle 1.2 | D18: Off Season | E18: Phase II | G18: Saturday | J18: Saturday | K18: Technical Introducation | N18: 1. **Warm Up B** | O18: 2. **Special Endurance** 2 sets of 3x500m; or 2 sets of 2x900m; or 2 sets of 4x150m R= 2' & 6' All runs should be equal times | P18: 3. **Multiple Jump** Rudiment 2x 20-30m | Q18: 4. **Hurdle Mobility** 3x 5H Series 1-4 | R18: 5. **Weight Train** | S18: 6. **Cool Down** 5' Bike
A19: c-pRwTmeTI6DhJlI30e4Zw | C19: Cycle 1.2 | D19: Off Season | E19: Phase II | G19: Sunday | J19: Sunday | K19: Technical Introducation | N19: Active Rest or Complete Rest
A20: 2uy-wHE6SY6O-qa0AQeKsQ | C20: Cycle 1.3 | D20: Off Season | E20: Phase III | H20: Monday | J20: Monday | N20: 1. **Warm Up A** | O20: 2. **Acceleration Dev** 4 sets of 3x30m; Can use hurdles R = 2' & 3-4' 1x300m Speed Endurance Run | P20: 3. **Multiple Jump** 2x 20-40m Rudiment w/ med ball | Q20: 4. **Weight Train** Jog, Skip, Side Shuffle | R20: 5. **Cool Down** Jog, Skip, Side Shuffle
A21: O-T1Akw5SRGkzC5gBqxpeA | C21: Cycle 1.3 | D21: Off Season | E21: Phase III | H21: Tuesday | J21: Tuesday | N21: 1. **Warm Up B** | O21: 2. **Jump Tech** Or Sprint Tech: 8-10 x 80m dribble bleeds (40/40) R = 3' - 5' | P21: 3. **General Strength** Pillar or Pedestal | Q21: 4. **Multiple Throw** Gas | R21: 5. **Hurdle Mobility** 5x5H, Series 1-4 | S21: 6. **Weight Train** | T21: 7. **Cool Down** 5' bike, mixed speed
A22: 1E4108DjTa6zp2Xe4KD1FQ | C22: Cycle 1.3 | D22: Off Season | E22: Phase III | H22: Wednesday | J22: Wednesday | N22: 1. **Warm Up B** | O22: 2. **Speed Development** 3x50-60m (can use hurdles) R=3' | P22: 3. **Anaerobic Power Ladder** x3 runs (e.g. 5,4,3) R=4' | Q22: 4. **Multiple Jump** RIP x3 | R22: 5. **Weight Train** | S22: 6. **Cool Down** Jog/Skip
A23: OzCBh4K5TjmmpQIcSHlZlQ | C23: Cycle 1.3 | D23: Off Season | E23: Phase III | H23: Thursday | J23: Thursday | N23: 1. **Warm Up B or A** | O23: 2. **Recovery Runs** | P23: 3. **General Strength** Bataan or Waterloo (cycle each week) | Q23: 4. **Multiple Throw** Tank | R23: 5. **Cool Down** 5' Bike Easy
A24: eoDuhh.pTNOPnaAR4to-xQ | C24: Cycle 1.3 | D24: Off Season | E24: Phase III | H24: Friday | J24: Friday | N24: 1. **Warm Up B** | O24: 2. **Jump Tech** Or Acceleration Development 3 sets of 3x30m R= 2' & 4' | P24: 3. **Multiple Throw** 3x Bomb or Grenade (cycle each week) | Q24: 4. **Weight Train** | R24: 5. **Cool Down** 5' Jog/Skip
A25: WWs-qAPeQguK7U5L-aNabQ | C25: Cycle 1.3 | D25: Off Season | E25: Phase III | H25: Saturday | J25: Saturday | N25: 1. **Warm Up B or C** | O25: 2. **Special Endurance / Alactic Prep** 3x900m, R=2'-3'; or 3x700m, R=2'-3'; or 2 sets of 4x150m, R= 4' & 6' | P25: 3. **Hurdle Mobility** 3x 5H Series 1-4 | Q25: 4. **General Strength** Verdun 2x 20-30m | R25: 5. **Weight Train** Optional | S25: 6. **Cool Down** Jog 3'-5'
A26: VMsb654VQou7q8EQh0ffOA | C26: Cycle 1.3 | D26: Off Season | E26: Phase III | H26: Sunday | J26: Sunday | N26: Active Rest or Complete Rest
A27: 4NxDidP0T1myMc2X5BvVzQ | C27: Cycle 1.4 | D27: Off Season | E27: Phase IV | I27: Monday | J27: Monday | N27: 1. **Warm Up A** | O27: 2. **Acceleration Dev** 3-4 sets of 3x30m; Can use hurdles R = 2' & 3-4' 1x250m Speed Endurance Run | P27: 3. **Multiple Jump** 1-2x 20-40m Rudiment w/ med ball | Q27: 4. **Weight Train** | R27: 5. **Cool Down** Jog, Skip, Side Shuffle
A28: C.nOAzFdQwWC1j0Q-h1UDw | C28: Cycle 1.4 | D28: Off Season | E28: Phase IV | I28: Tuesday | J28: Tuesday | N28: 1. **Warm Up B** | O28: 2. **Jump Tech** Or Sprint Tech: 8-10 x 70m dribble bleeds (40/40) R = 3' - 5' | P28: 3. **General Strength** Pillar or Pedestal | Q28: 4. **Multiple Throw** Gas | R28: 5. **Hurdle Mobility** 3x5H, Series 1-4 | S28: 6. **Weight Train** OPTIONAL | T28: 7. **Cool Down** 5' bike, mixed speed
A29: t001oy9uQTOHpXblTt6TLQ | C29: Cycle 1.4 | D29: Off Season | E29: Phase IV | I29: Wednesday | J29: Wednesday | N29: 1. **Warm Up B** | O29: 2. **Speed Development** 4x50-60m (can use hurdles) R=3' | P29: 3. **Anaerobic Power Ladder** x3 runs (e.g. 5,4,3) R=4' | Q29: 4. **Multiple Jump** RIP x3 | R29: 5. **Weight Train** | S29: 6. **Cool Down** Jog/Skip
A30: Yq5QIOS6RiqaS33fI9JBPA | C30: Cycle 1.4 | D30: Off Season | E30: Phase IV | I30: Thursday | J30: Thursday | N30: 1. **Warm Up B or A** | O30: 2. **Recovery Runs** | P30: 3. **General Strength** Bataan or Waterloo (cycle each week) | Q30: 4. **Multiple Throw** Tank | R30: 5. **Cool Down** 5' Bike Easy
A31: Qv9pckhXSYexKfysoSLp4Q | C31: Cycle 1.4 | D31: Off Season | E31: Phase IV | I31: Friday | J31: Friday | N31: 1. **Warm Up B** | O31: 2. **Jump Tech** Or Acceleration Development 3 sets of 3x30m R= 2' & 4' | P31: 3. **Multiple Throw** 3x Bomb or Grenade (cycle each week) | Q31: 4. **Weight Train** | R31: 5. **Cool Down** 5' Jog/Skip
A32: Y2TYOvooQzC5VmVbSCWX.Q | C32: Cycle 1.4 | D32: Off Season | E32: Phase IV | I32: Saturday | J32: Saturday | N32: 1. **Warm Up B or C** | O32: 2. **Special Endurance / Alactic Prep** 3x800m, R=3'; or 3x700m, R=3'; or 2 sets of 4x150m, R=5' & 6' | P32: 3. **Hurdle Mobility** 3x 5H Series 1-4 | Q32: 4. **General Strength** Verdun 2x 20-30m | R32: 5. **Weight Train** Optional | S32: 6. **Cool Down** Jog 3'-5'
A33: vCWCkcy2QMO5YgU3PEenTQ | C33: Cycle 1.4 | D33: Off Season | E33: Phase IV | I33: Sunday | J33: Sunday | N33: Active Rest or Complete Rest
A34: jnIR10rITW2wA0GR9hLisA | C34: Cycle 2.1 | D34: Early Season | E34: Phase I | J34: Monday | N34: 1. **Warm Up A** | O34: 2. **Acceleration Dev** 3-4 sets of 3x30m; Flat or hurdles R = 2' & 3-4' | P34: 3. **Anaerobic Power** 1x300 or 350m | Q34: 4. **Multiple Throw** Grenade x3 w/ 5k shot put | R34: 5. **Weight Train** | S34: 6. **Cool Down** Jog, Skip, Side Shuffle
A35: vEI9p37pS7ydwtuaRnoojw | C35: Cycle 2.1 | D35: Early Season | E35: Phase I | J35: Tuesday | N35: 1. **Warm Up B** | O35: 2. **Jump Tech** Or Sprint Tech: 8-10 x 60m dribble bleeds (30/30) R = 3' - 5' | P35: 3. **General Strength** Pillar or Pedestal (cycle each week) | Q35: 4. **Multiple Throw** Gas | R35: 5. **Weight Train** OPTIONAL | S35: 6. **Cool Down** 5' bike, mixed speed
A36: seQKi0vSQBaUTmP7n6hpMg | C36: Cycle 2.1 | D36: Early Season | E36: Phase I | J36: Wednesday | N36: 1. **Warm Up B** | O36: 2. **Hurdle Speed Development** 4-6 x 6-7H (blocks) R=4' | P36: 3. **Anaerobic Power Ladder** 450, 400, 300 - fast! R=5' | Q36: 4. **Multiple Jump** RIP x3-5 | R36: 5. **Weight Train** | S36: 6. **Cool Down** Jog/Skip
A37: iEV.MyO9QoC.TpuMwnNeKw | C37: Cycle 2.1 | D37: Early Season | E37: Phase I | J37: Thursday | N37: 1. **Warm Up B or A** | O37: 2. **Recovery Runs** 20' fartlek w/ 1' on & 3' off | P37: 3. **General Strength** Bataan or Waterloo (cycle each week) | Q37: 4. **Multiple Throw** Tank | R37: 5. **Cool Down** 5' Bike Easy
A38: T.fRkn-wQ7GfIyqRo3VnNQ | C38: Cycle 2.1 | D38: Early Season | E38: Phase I | J38: Friday | N38: 1. **Warm Up B** | O38: 2. **Jump Tech** Or Acceleration Development 3 sets of 3x30m R= 2' & 5' | P38: 3. **Multiple Throw** Bomb x3 | Q38: 4. **Weight Train** | R38: 5. **Cool Down** 5' Jog/Skip
A39: YpSIqQE9QFyGpHR.D5kWBQ | C39: Cycle 2.1 | D39: Early Season | E39: Phase I | J39: Saturday | N39: 1. **Warm Up B or C** | O39: 2. **Special Endurance / Alactic Prep** 2 sets of 2x300m; or 2 sets of 2x250m; or 2 sets of 2x150m R=3' & 6'-8' | P39: 3. **Hurdle Mobility** 3x 5H Series 1-4 | Q39: 4. **General Strength** Verdun 2x 20-30m with Med Ball | R39: 5. **Weight Train** Optional | S39: 6. **Cool Down** Jog 3'-5'
A40: m3svGZ04S16iwyOVAkQb.Q | C40: Cycle 2.1 | D40: Early Season | E40: Phase I | J40: Sunday | N40: **Tempo Endurance Run** 20' tempo run, increase pace every 5' - finish fast! (Replaces Saturday special endurance session from previous cycles)
...

Sheet Events
A1: 🔒 Row ID | B1: Image | C1: Event | D1: Type | E1: Technical Model | F1: Mark Detail | G1: Warm Up | H1: Notes | I1: Video
A2: r--EEJbER2Sbt9yPkS3wSQ | B2: https://storage.googleapis.com/glide-prod.appspot.com/uploads-v2/cMkSU7tNCGrXdOICNUYw/pub/4YEX1fv9M0SSXOvdJCrJ.png | C2: 100m | D2: Acceleration | F2: Distance to Blocks
A3: a.-R67zDHRtOItUQgO8xx9A | B3: https://storage.googleapis.com/glide-prod.appspot.com/uploads-v2/cMkSU7tNCGrXdOICNUYw/pub/eGUPOSlsmJ5jbv5veTNw.png | C3: 200m | D3: Max Velocity | F3: Distance to Blocks
A4: N3oMSRleSdWcgPmCRXsCGg | B4: https://storage.googleapis.com/glide-prod.appspot.com/uploads-v2/cMkSU7tNCGrXdOICNUYw/pub/4xKeXALc5ARfvJdKPP3k.png | C4: 400m | D4: Speed Endurance | F4: Distance to Blocks
A5: 3h7c.cbsStOqlkrzOPUL5Q | B5: https://storage.googleapis.com/glide-prod.appspot.com/uploads-v2/cMkSU7tNCGrXdOICNUYw/pub/1Jkx9dSK3dX98297Bvup.png | C5: Long Distance | D5: Endurance
A6: wpJkV0wjQNuz8e0oZe.fsw | B6: https://storage.googleapis.com/glide-prod.appspot.com/uploads-v2/cMkSU7tNCGrXdOICNUYw/pub/JBN4bnhqDRceNz3TkMNk.png | C6: 100m Hurdles | D6: Max Velocity | F6: Distance to Blocks
A7: WGbcUOnJRGeoF9lYLb9U8g | B7: https://storage.googleapis.com/glide-prod.appspot.com/uploads-v2/cMkSU7tNCGrXdOICNUYw/pub/QKbDhJjHLafMy4fPXCEP.png | C7: 110m Hurdles | D7: Endurance | F7: Distance to Blocks
A8: a.aMNjL9RDSvL9ChJzAeWQ | B8: https://storage.googleapis.com/glide-prod.appspot.com/uploads-v2/cMkSU7tNCGrXdOICNUYw/pub/TduwoOOG3FIYDf03kO0l.png | C8: 400m Hurdles | F8: Distance to Blocks
A9: KugVk0dpTXufaWyvISbDGw | B9: https://storage.googleapis.com/glide-prod.appspot.com/uploads-v2/cMkSU7tNCGrXdOICNUYw/pub/SXHtQggn0tkOzn13kRIf.png | C9: Steeple | D9: Lift
A10: tbRzi8GmQqq8Ob3Aq07EUg | B10: https://storage.googleapis.com/glide-prod.appspot.com/uploads-v2/cMkSU7tNCGrXdOICNUYw/pub/FbaUK96qv7ANGsdGT9E1.png | C10: Long Jump | E10: PUSH out of back, cover ground, powerful. - Gradually increase stride frequency. Long & powerful, smoothly to quick & fast. Steer to the board with periphery, target back edge of the board, planting with full foot dorsiflexed. | F10: Full / Mid / Short Approach
A11: Gr0EtHNcRnufB6SsBK9-BA | B11: https://storage.googleapis.com/glide-prod.appspot.com/uploads-v2/cMkSU7tNCGrXdOICNUYw/pub/PVbaFWrMPQ1mnxO4vje9.png | C11: Triple Jump | D11: Jump | E11: Technical Model | F11: Full / Mid / Short Approach
A12: cOODu77pQEaTZoSSu7dhSQ | B12: https://storage.googleapis.com/glide-prod.appspot.com/uploads-v2/cMkSU7tNCGrXdOICNUYw/pub/FNqpvqylW8wCq8m5os7s.png | C12: High Jump | D12: Throw | E12: - Cover ground out of back - Keep smooth lean into curve - Grab with full foot into curve - Maintain pressure & stiff lean - "Ride the elevator" through takeoff - Let hips float over, frog legs - Tuck chin to snap legs over bar. | F12: Full / Short Approach
A13: NOnGCuFQR7Kvf9E-Uh6xbg | B13: https://storage.googleapis.com/glide-prod.appspot.com/uploads-v2/cMkSU7tNCGrXdOICNUYw/pub/xTCtlhNAleNyHY7mr25U.png | C13: Pole Vault | D13: Hurdle | F13: Full / Mid / Short Approach | I13: https://www.youtube.com/watch?v=8Q7R6Kqn5gw
A14: tVEuKkTsRPKi7iWO16y01w | B14: https://storage.googleapis.com/glide-prod.appspot.com/uploads-v2/cMkSU7tNCGrXdOICNUYw/pub/Ds2y9HNQyExqQLqiB6Ea.png | C14: Shot Put
A15: ej-vSzaIQciMnlLGQHMDzQ | B15: https://storage.googleapis.com/glide-prod.appspot.com/uploads-v2/cMkSU7tNCGrXdOICNUYw/pub/IWxrc13J8OoQJtyxPOZx.png | C15: Discus
A16: SQ1UJ4yxRqq6gx4-8lDGfw | B16: https://storage.googleapis.com/glide-prod.appspot.com/uploads-v2/cMkSU7tNCGrXdOICNUYw/pub/OboCNX6lWCUDKBl4ewzC.png | C16: Javelin
A17: OS7zSdHyQVGocgVMNTrZqg | B17: https://storage.googleapis.com/glide-prod.appspot.com/uploads-v2/cMkSU7tNCGrXdOICNUYw/pub/z4NiyBI11hyPCCI5W1Q3.png | C17: Hammer
A18: TNLyq3vxTE6ZIV.rDntjzg | C18: Weight
A19: 2gXogiEcRj6WgcJCPE278A | B19: https://storage.googleapis.com/glide-prod.appspot.com/uploads-v2/cMkSU7tNCGrXdOICNUYw/pub/VwvPBfQPxlqprnE2YopR.png | C19: 800m | D19: Lactic Threshold
A20: TpZULe12Q2eDCHKsrdYQEw | B20: https://storage.googleapis.com/glide-prod.appspot.com/uploads-v2/cMkSU7tNCGrXdOICNUYw/pub/UBvkuO3PVE3ZNArr9RNp.png | C20: 1500m | D20: Lactic Threshold
A21: 5rL2grFeRTukBRDxOyKgPw | B21: https://storage.googleapis.com/glide-prod.appspot.com/uploads-v2/gtfdDGd9EKORi4XOZq7P/pub/FdzQPQhonT0KugDe1Co6.jpg | C21: Racewalk
A22: eM8buciRQfaaszpxG38bpg
A23: oPjqRyEeR-2.w.xr8-V.2Q
A24: YZ2UIM9uQG-poJd2RlJpHg
A25: TuZm43pvQlmb7q9QoZzf7g
A26: RbD7EbuWS5GLEon2nHfZqQ

Sheet Form Results
A1: 🔒 Row ID | B1: Email | C1: Name | D1: Date | E1: Workout Description | F1: Performance Metrics | G1: Notes | H1: Event | I1: Conditioning Type | J1: Competition? | K1: Link to Video | L1: Icon
A15: TVr7PLUlSTiXECTac4mnWQ | B15: curtisbeach12@gmail.com | D15: 44187.68 | E15: Trek, Pedestal, Pillar, Gas | 111,121 | G15: Sore from yesterday. Core sore from RIP. Woke up night prior because of soreness, probably didn't eat enough. | I15: Jump | J15: FALSE
A16: 4dOA9v7QR-OwWb7kt.jHLg | B16: curtisbeach12@gmail.com | D16: 44186 | E16: 3x 10, 20, 30 + RIP | G16: Accels felt good. Rhythmic is fast, complete arm swing w/ powerful pushes. | I16: Acceleration | J16: FALSE
A17: erGr1CDVQ02IwYDRd64MsA | B17: curtisbeach12@gmail.com | D17: 44185 | E17: Weight: 191, body comp iffy | G17: Less muscle more fat body comp. Typically 183 with muscle. | J17: FALSE
A18: WaaRpywZTni5ithFyuPbEQ | B18: curtisbeach12@gmail.com | D18: 44188 | E18: 4x70m sprints | Kilimanjaro | G18: Very very cold 🥶 | I18: Max Velocity | J18: FALSE
A19: 7iP-4g9eThq7dY596fT85A | B19: curtisbeach12@gmail.com | D19: 44190 | E19: 4x3 20m hill sprints / OHB 4x5 | G19: Sprints felt good | I19: Acceleration | J19: FALSE
A20: bZ9-tFd6S4KOUzJ1r.kXYA | B20: curtisbeach12@gmail.com | D20: 44191.965 | E20: 6x90m / 4x90m, 10x5 hurdle hops, hurdle mob | G20: Speed endurance is faaar from there. Got to 4 on first set before things went south | I20: Speed Endurance | J20: FALSE
A21: YoKzc2vdQ7-fZJv8cGcOLQ | B21: curtisbeach12@gmail.com | D21: 44194.761 | E21: Trek x2, Bataan/Pillar/Gas, partial Ancillary A | G21: Ancillary A great for hams & hip mobility | I21: Jump | J21: FALSE
A22: vg6I0iA9TJmkDPIcWzTLbQ | B22: curtisbeach12@gmail.com | D22: 44193 | E22: 4x 10-20-30, RIP | G22: Accels felt good. Beware of tech getting worse as practice goes on. Gotta feel it. | I22: Acceleration | J22: FALSE
A23: iVqpArEWT92Q2Y3mHL9MSg | B23: curtisbeach12@gmail.com | D23: 44195.732 | E23: 5x 70m, Everest, Lift | G23: L achilles slightly sore but in tact | I23: Max Velocity | J23: FALSE
A24: iMw7MXtWQDyN.R2QWocdHA | B24: curtisbeach12@gmail.com | D24: 44198 | E24: 2x6 80m slight hill sprints (2' & 5'), 10x5 hurdle hops, 5x5 hurdle mobility series | I24: Speed Endurance | J24: FALSE
A25: YRNlgXUIQM6uFssb8ivC2g | B25: curtisbeach12@gmail.com | D25: 44197 | E25: Light run | J25: FALSE
A26: KAKjx7BtSX2xPsOLOfPW6A | B26: curtisbeach12@gmail.com | D26: 44196 | E26: Light run | J26: FALSE
A27: z4HYSjEORp6YCPatlRkTHg | B27: curtisbeach12@gmail.com | D27: 44200 | E27: 4(3x30m), RIP, Lift | G27: Sore, feeling neural fatigue. Sleep beginning to be disrupted. | I27: Acceleration | J27: FALSE
A28: a-beR.LYDT9SVdoNkHPbddw | B28: curtisbeach12@gmail.com | D28: 44201 | E28: Trek, Pedestal/Pillar, Gas, Ancillary B | G28: Sore, woke up at night a little hungry | I28: Jump | J28: FALSE
A29: 4xAmITMIR6u-2UOx3sLbxg | B29: curtisbeach12@gmail.com | D29: 44202 | E29: 5 4 3 2 w/ 2’ (32-68-1:26, 33-69, 47, 29.0) Windy Kilimanjaro Lift | G29: Ugh... mentally tough to get there and not physically there either. Didn’t quite go lactic. Good keeping form in check & not being early w/ toe. | I29: Speed Endurance | J29: FALSE
A30: tQWSdA05T1CnCA9J7zcSxw | B30: curtisbeach12@gmail.com | D30: 44208 | E30: 2x10,20,30 / 2x3x30 RIP Accel Lift | G30: Bench very low + other strength levels. 4x4 at 175 and lower reps also there. | I30: Acceleration | J30: FALSE
A31: kTfsI0YaR7m.o3RJGiXqPg | B31: curtisbeach12@gmail.com | D31: 44206 | E31: 2(5x120m) 10x5 hurdle hops Hurdle walk overs | I31: Speed Endurance | J31: FALSE
A32: eAFuGf2nS1eZKuc8orm62w | B32: curtisbeach12@gmail.com | D32: 44210 | E32: 5,4,3,150 w/ 4’ Rudiment 1x20m Bomb Lift | F32: 60-1:17, 62, 44.0, 20 | G32: Good lactic / aerobic blend | I32: Lactic Threshold | J32: FALSE
A33: gf4WHMpWQ6mffO1tY9J9JA | B33: curtisbeach12@gmail.com | D33: 44209 | E33: Trek Extensive Tempo: 111, 212 Gas | I33: Jump | J33: FALSE
A34: RiizEkavQB-lOsRVJ6.5EQ | B34: curtisbeach12@gmail.com | D34: 44211 | E34: WU A, Trek, Bataan/Waterloo/Tank/Hurdle walk overs | I34: Jump | J34: FALSE
A35: aacM3jt9RZub9mAsW4faEA | B35: curtisbeach12@gmail.com | D35: 44213 | E35: Easy Run - light fartlek | J35: FALSE
A36: FSP6IVuBRfe-47LA7S20ug | B36: curtisbeach12@gmail.com | D36: 44214 | E36: 3(3x3H), 1(3x30m), Shot Put, Lift | G36: Lots of volume, sore & could hardly sleep later. *Space before hurdle, get RL down FAST on back side. | H36: 110m Hurdles | I36: Acceleration | J36: FALSE
A37: D0vVlpRHR.qtUu46QY3QgA | B37: curtisbeach12@gmail.com | D37: 44214 | E37: Shot Put | G37: Learn a lot by teaching. It’s a transfer of power and directing energy to right places | H37: Shot Put | J37: FALSE
A38: dWk1huvtT8Kogt6-MB7Gsw | B38: curtisbeach12@gmail.com | D38: 44218 | E38: 2(5x120) w/ 2’ & 5g’ 5x5 Hurdle hops Lateral rudiment reps | I38: Speed Endurance | J38: FALSE
A39: Z3Y8WOj9R6aH83sg9CWCCA | B39: curtisbeach12@gmail.com | D39: 44216 | E39: 5,4,3,2 straight on tobacco rd | G39: Hard to hit effort levels w/o track metrics. Not as high intensity | I39: Lactic Threshold | J39: FALSE
A40: ah2aKd5iTuu2Ps7YG-HWkQ | B40: curtisbeach12@gmail.com | D40: 44217 | E40: Light run | J40: FALSE
A41: z.Yc5ZzOSVCs8I9lv7A6DQ | B41: curtisbeach12@gmail.com | D41: 44215 | E41: Fartlek + Waterloo | J41: FALSE
A42: QJ8NYe3vTe27Gpag7FaO-Q | B42: ed.fye@doane.edu | D42: 44299 | E42: 6:00-15 min elliptical 11:00- 12 min rowing- 20 min biking. | J42: FALSE

Sheet Choice Selection
A1: 🔒 Row ID | B1: Circuit Choice | C1: Circuit Output | D1: Calc Choice | E1: Calc Output | F1: Event Choice | G1: Event Display as | H1: Event Output | I1: Data Choice | J1: Inventory Link
A2: YIByS9f6S2mMfF6FA3TQEA | B2: Circuits | C2: Circuits | D2: Prediction | E2: Prediction | F2: Dec | G2: Decathlon | I2: Time
A3: pQk79NcMQ0e0EwKD0qM9CA | B3: General | D3: Actual | F3: Hep | G3: Heptathlon | I3: Distance
A4: Buu1VqiWSAKZyYWyqPkOrw | G4: Indoor Heptathlon
A5: dU0-Ck78SS6EflKEnZeuEg | G5: Indoor Pentathlon

Sheet Calculator
A1: 🔒 Row ID | B1: Athlete | C1: Event Display | D1: Email
A2: K26H5fbrQfKrjSTVDSEvUg
A3: LqPcj5ZqTka8BzZDkNE2zA | B3: Evan Lee | C3: Dec
A4: 9jx8c.RwTzKX8p5QawsLJw | B4: Kyle Foltz | C4: Dec
A5: n1wGydQUQE-4DaP.okgJRQ | B5: Jacob Sobota | C5: Hep (i)
A6: a-1AfWws0RIu8-4f8i-3kEA | B6: Harry Lord | C6: Hep (i)
A7: R1Ktl9ZqTZOG9okMDS6CDw | B7: Kate Kutzer | C7: Pent (i)
A9: Nw7qqZY-QFOZl12jiO6ang | B9: Gage Knight | C9: Hep (i)
A10: DhJWJMlWSGaWCEUel6IZmw | B10: Erin Marsh | C10: Hep
A11: 0nPcXjSiRxCgKVTcSYSDqg | B11: Lara | C11: Hep
A12: DfSyqjO1Sde4dfErgTb0Cg | B12: Alex | C12: Hep (i)
A13: gg-iTlJaRJKTgsgtirw3OA | B13: Curtis | C13: Dec
A14: yU.9yeZFRFmIBwCKPwHjBw | B14: Dan | C14: Dec | D14: curtisbeach12@gmail.com
A15: M0wezxBnTOWvNTp88Ipv3g | B15: Dave | C15: Dec | D15: curtisbeach12@gmail.com
A16: xEswHRCHTHmQZ7ftXJlccg | B16: Dan | C16: Dec
A17: heiOaBv2SIaHVly0OrcMGA | B17: Olympic Games | C17: Dec | D17: meengis@gmail.com

Sheet Stopwatch
A1: 🔒 Row ID | B1: Date | C1: Meh
A2: WhfQCOmeRVuIwjPV-un5EQ | B2: =TODAY() -> 46216

Sheet Overviews
A1: Parent | B1: Name | C1: Image | D1: Compare Image | E1: Title Inventory | F1: Title Event Pages | G1: Title Training Log
A2: Training Log | B2: Log | C2: https://storage.googleapis.com/glide-prod.appspot.com/uploads-v2/gtfdDGd9EKORi4XOZq7P/pub/yAMh4rui8XcSlNFMCubf.jpg | D2: https://storage.googleapis.com/glide-prod.appspot.com/uploads-v2/gtfdDGd9EKORi4XOZq7P/pub/jb76QsebWwGIwmT4GyZu.png | E2: Circuits & How-to's | F2: Goals, Cues, Marks Organized | G2: Interactive & Sharable Training Log
A3: Training Log | B3: Add Items | C3: https://storage.googleapis.com/glide-prod.appspot.com/uploads-v2/gtfdDGd9EKORi4XOZq7P/pub/gGO57ZWcYQAMnw589Cur.jpg
A4: Training Log | B4: Filter Entries | C4: https://storage.googleapis.com/glide-prod.appspot.com/uploads-v2/gtfdDGd9EKORi4XOZq7P/pub/qwxaJRFO3z7KRMgHufXl.jpg
A5: Training Log | B5: Clear Details | C5: https://storage.googleapis.com/glide-prod.appspot.com/uploads-v2/gtfdDGd9EKORi4XOZq7P/pub/3vWAqPU7s2Tkmb4cdtYZ.jpg
A6: Training Management | B6: Profiles | C6: https://storage.googleapis.com/glide-prod.appspot.com/uploads-v2/gtfdDGd9EKORi4XOZq7P/pub/C4qaJPpWiM5xRr6iYZEg.jpg
A7: Training Management | B7: Event Pages | C7: https://storage.googleapis.com/glide-prod.appspot.com/uploads-v2/gtfdDGd9EKORi4XOZq7P/pub/c1Gqhj9LDpxQG8Z3AeAz.jpg
A8: Training Management | B8: Edit Profile | C8: https://storage.googleapis.com/glide-prod.appspot.com/uploads-v2/gtfdDGd9EKORi4XOZq7P/pub/UlK3XqTzy2ULFpNPM3hB.jpg
A9: Exercise Inventory | B9: Inventory | C9: https://storage.googleapis.com/glide-prod.appspot.com/uploads-v2/gtfdDGd9EKORi4XOZq7P/pub/DLBWjcLRIc2yggYK4mDs.jpg
A10: Exercise Inventory | B10: Circuit | C10: https://storage.googleapis.com/glide-prod.appspot.com/uploads-v2/gtfdDGd9EKORi4XOZq7P/pub/BhVozpBm9Ciw5BETUqfO.jpg
A11: Exercise Inventory | B11: Exercise | C11: https://storage.googleapis.com/glide-prod.appspot.com/uploads-v2/gtfdDGd9EKORi4XOZq7P/pub/hit3kTw7OjLxRiLbsorD.jpg
A13: Welcome | B13: Welcome | C13: https://storage.googleapis.com/glide-prod.appspot.com/uploads-v2/gtfdDGd9EKORi4XOZq7P/pub/YvzcXeanZNCDLjH3xMFq.png

Sheet Metric & Time Cards
A1: 🔒 Row ID | B1: Metric | C1: Type | D1: Description | E1: Image
A2: fwG4zwFtTV64qdn-XNRn3A | B2: Metric One | C2: Metric | D2: Chart Distances & Scores | E2: https://storage.googleapis.com/glide-prod.appspot.com/uploads-v2/gtfdDGd9EKORi4XOZq7P/pub/EoZU2W3dfKXH6C0EfXIt.jpg
A3: Q5KhQOcPRweAsy7Xbg1csg | B3: Metric Two | C3: Metric | D3: Chart Distances
A4: 8AMUsM-rSLKlhbzhFLlK4Q | B4: Metric Three | C4: Metric | D4: Chart Distances
A5: neIVnn-tRYCwJd5Ryn0LlQ | B5: Metric Four | C5: Metric | D5: Chart Times
A6: 5.gogD0aQ6KLvLlJlpiiXw | B6: Time One | C6: Time
A7: CXA3JtKyQty4GV0tsllQVA | B7: Time Two | C7: Time
A8: iq2EYvgWQm6L.hb-ivDDfA | B8: Time Three | C8: Time
A9: YCgIcC6kT0qYvPCWp4NSSg | B9: Time Four | C9: Time | E9: https://storage.googleapis.com/glide-prod.appspot.com/uploads-v2/gtfdDGd9EKORi4XOZq7P/pub/F9sdwMbA8lzwT7NPQIBn.jpg

Sheet Metrics
A1: 🔒 Row ID | B1: Date One | C1: Email | D1: Metric One | E1: Notes One | F1: Metric Two | G1: Metric Three | H1: Metric Four | I1: Notes Two | J1: Notes Three | K1: Notes Four | L1: Date Two | M1: Date Three | N1: Date Four
A3: xYm8CianQBeBOq4tdjyYKw | B3: 44265.412 | C3: alexandraeapple@gmail.com | D3: 4
A20: ktdwPf9jTNenpMDa217LMA | B20: 44271.896 | C20: curtisbeach.12@gmail.com | D20: 5
A21: JgwYle0TQgCvzyz5QUcttw | B21: 44491.493 | C21: felixlovetorun@gmail.com | D21: 14.5
A22: cuAxz3XsSgOVspvaaEyTQw | B22: 44895.959 | C22: nblake.1119@gmail.com | E22: 473829

Sheet Times
A1: 🔒 Row ID | B1: Date One | C1: Email | D1: Seconds Entry | E1: Minutes Entry | F1: Hours Entry | G1: Notes | H1: Date Two | I1: Date Three | J1: Date Four
A3: BSJouZrjTgmB.CqgDCkpEw | B3: 44265.453 | C3: curtisbeach12@gmail.com | D3: 6.67
A4: u-uE5eUxT7isxn5NXnH2dA | B4: 44267.455 | C4: curtisbeach12@gmail.com | D4: 12
A5: 3pQn8ggYRQC8RhDu2aeHxQ | B5: 44267.833 | C5: curtisbeach12@gmail.com | D5: 46
A6: F346AjN6RKKyAMlRWKLpUg | C6: curtisbeach12@gmail.com | D6: 44 | H6: 44267.835
A7: dNZXoYINQHCLvDqpeA7Afg | C7: curtisbeach12@gmail.com | D7: 4 | E7: 4 | I7: 44267.839
A8: v15xSd9YSkChxvLOB0Liww | C8: curtisbeach12@gmail.com | D8: 37.5 | E8: 2 | F8: 2 | J8: 44267.841
A9: IMMsZGZpQyis-vAEqS8J5g | C9: curtisbeach12@gmail.com | D9: 42 | H9: 44267.959
A10: KFJ9XbO8T9maPszoveYLZA | C10: curtisbeach12@gmail.com | D10: 2 | E10: 1 | H10: 44267.959

Sheet Welcome
A1: 🔒 Row ID | B1: ID | C1: Name | D1: Image | E1: Details
A2: XRl7Jtz1R76LfrWL-Uk2Dw | B2: 1 | C2: Get on iPhone | D2: https://storage.googleapis.com/glide-prod.appspot.com/uploads-v2/gtfdDGd9EKORi4XOZq7P/pub/niuXlNZmoVl2cjZZeWd7.jpg
A3: nJ.pNmYbRHGSY39VBe7RWA | B3: 2 | C3: Get on Android | D3: https://storage.googleapis.com/glide-prod.appspot.com/uploads-v2/gtfdDGd9EKORi4XOZq7P/pub/MZE6Kvyy3CIT0xdF4sGH.jpg
A4: UhbDgiPdSDOtCgnOtqLo4g | B4: 3 | C4: Exercise Inventory
A5: xe8nxb0nSjOmwtZwW-9EMA | B5: 4 | C5: Training Log | E5: Maintain what you learn from practice to practice.
A6: oWsLirPlT3CpD3hytEj4GA | B6: 5 | C6: Training Management

Sheet App Metadata
A1: Last Automatic Refresh Initiated | B1: Last Manual Refresh Requested
B2: 45932.818

Sheet App Logins
A1: Time | B1: Email | C1: Agreed
A2: 2020-08-18T18:38:31.073Z | B2: curtisbeach12@gmail.com | C2: FALSE
A3: 2020-11-17T19:07:48.184Z | B3: curtisbeach12@gmail.com | C3: FALSE
A4: 2020-11-26T17:13:34.341Z | B4: curtisbeach21@gmail.com | C4: FALSE
A5: 2020-12-01T13:22:33.105Z | B5: whimsical-star-566@anonymous.appuser.io | C5: FALSE
A6: 2020-12-01T13:54:29.667Z | B6: accurate-language-128@anonymous.appuser.io | C6: FALSE
A7: 2020-12-01T14:10:50.698Z | B7: cur.tisbeach12@gmail.com | C7: FALSE
A8: 2020-12-01T14:20:25.935Z | B8: curt.isbeach12@gmail.com | C8: FALSE
A9: 2020-12-01T14:53:48.239Z | B9: curti.sbeach12@gmail.com | C9: FALSE
A10: 2020-12-01T14:55:18.056Z | B10: curti.sbeach12@gmail.com | C10: FALSE
A11: 2020-12-01T14:57:37.524Z | B11: curtis.beach12@gmail.com | C11: FALSE
A12: 2020-12-01T15:28:03.162Z | B12: curtisb.each12@gmail.com | C12: FALSE
A13: 2020-12-01T15:37:26.690Z | B13: curtisbe.ach12@gmail.com | C13: FALSE
... A203: 2025-09-29T20:11:57.903Z | B203: sonja.rizzardi@gmail.com | C203: TRUE

Sheet App Comments
A1: ID | B1: Topic | C1: Username | D1: Email | E1: Time | F1: Comment
A2: CIP9BlFKN6jqyAZGMzO6 | B2: Announcements | D2: curtisbeach12@gmail.com | E2: 44128.018 | F2: k
A3: bmfA5BLZsskGVItcJdAP | B3: $$ GLOBAL_CHAT $$ | C3: Curtis Beach | E3: 44135.805 | F3: ok
A4: Q12ZeBnWUP7Y60cC6iXv | B4: $$ GLOBAL_CHAT $$ | C4: AJ Beach | D4: meengis@gmail.com | E4: 44135.805 | F4: k
A5: 44dgpyiZ5M9repjzp5uo | B5: Curtis | C5: Curtis Beach | D5: curtisbeach12@gmail.com | E5: 44135.81 | F5: Okay
A6: 44dgpyiZ5M9repjzp5uo | B6: Curtis | C6: Curtis Beach | D6: curtisbeach12@gmail.com | E6: 44135.81 | F6: Okay

Sheet App Sales
A1: Purchaser name | B1: Purchaser email | C1: Purchased item | D1: Item SKU | E1: Amount | F1: Paid at | G1: Shipping City | H1: Shipping Country | I1: Shipping Address Line 1 | J1: Shipping Address Line 2 | K1: Shipping Postal Code | L1: Shipping State | M1: Processor Link | N1: Shipping Phone
A2: Curtis | B2: curtisbeach12@gmail.com | C2: TEST PURCHASE: Yearly | D2: 1 | E2: TEST PURCHASE: 29 | F2: 44155.518 | M2: https://dashboard.stripe.com/payments/pi_1HpYgwGWRsJ6qRMXnSR4V8Ua
A3: AJ | B3: meengis@gmail.com | C3: TEST PURCHASE: Yearly | D3: 1 | E3: TEST PURCHASE: 29 | F3: 44155.523 | M3: https://dashboard.stripe.com/payments/pi_1HpYnuGWRsJ6qRMXlofI7bcd
A4: SPO | B4: sposwald88@gmail.com | C4: TEST PURCHASE: One Year | D4: 1 | E4: TEST PURCHASE: 15 | F4: 44155.594 | M4: https://dashboard.stripe.com/payments/pi_1HpaOAGWRsJ6qRMXFJXSe0T7
A5: Test | B5: accurate-language-128@anonymous.appuser.io | C5: TEST PURCHASE: One Year | D5: 1 | E5: TEST PURCHASE: 15 | F5: 44166.589 | M5: https://dashboard.stripe.com/payments/pi_1HtZWhGWRsJ6qRMX79Fs42hV
A6: Curtis | B6: curtisbe.ach12@gmail.com | C6: One Year | D6: 1 | E6: 1 | F6: 44166.651 | M6: https://dashboard.stripe.com/payments/pi_1HtavPGWRsJ6qRMXY0tyj4vR
A7: Robyn | B7: dreamngold@gmail.com | C7: Free | D7: 0
B8: ryan.dorshorst@doane.edu | C8: Free | D8: 0
A9: USA | B9: beachathletics.12@gmail.com | C9: TEST PURCHASE: Buy for One Year | D9: 1 | E9: TEST PURCHASE: 29 | F9: 44226.756 | M9: https://dashboard.stripe.com/payments/pi_1IFNrnGWRsJ6qRMXlJS4Uiqa
A10: Test | B10: whimsical-star-566@anonymous.appuser.io | C10: TEST PURCHASE: Buy for One Year | D10: 1 | E10: TEST PURCHASE: 29 | F10: 44229.569 | M10: https://dashboard.stripe.com/payments/pi_1IGP5yGWRsJ6qRMXfm00D99B
A11: Test 01 | B11: c.urtisbeach12@gmail.com | C11: TEST PURCHASE: Buy for One Year | D11: 1 | E11: TEST PURCHASE: 29 | F11: 44229.579 | M11: https://dashboard.stripe.com/payments/pi_1IGPKoGWRsJ6qRMXl8QV7GVL
A12: Curtis Beach | B12: cu.rtisbeach12@gmail.com | C12: Test | D12: 3 | E12: 0.5 | F12: 44229.602 | M12: https://dashboard.stripe.com/payments/pi_1IGPplGWRsJ6qRMXy1MkPAWg
A13: Curtis Beach | B13: cur.tisbeach12@gmail.com | C13: Test | D13: 3 | E13: 0.5 | F13: 44229.604 | M13: https://dashboard.stripe.com/payments/pi_1IGPt0GWRsJ6qRMXGu1nqdlZ
A14: Curtis Beach | B14: curt.isbeach12@gmail.com | C14: Test | D14: 3 | E14: 0.5 | F14: 44237.793 | M14: https://dashboard.stripe.com/payments/pi_1IJNx6GWRsJ6qRMXnG0jS385
A15: Curtis Beach | B15: curti.sbeach12@gmail.com | C15: Test | D15: 3 | E15: 0.5 | F15: 44237.799 | M15: https://dashboard.stripe.com/payments/pi_1IJO5cGWRsJ6qRMXx0cdeIim
A16: Eddie Fye | B16: ed.fye@doane.edu | C16: Buy for Lifetime | D16: 2 | E16: 59 | F16: 44239.541 | M16: https://dashboard.stripe.com/payments/pi_1IK1FFGWRsJ6qRMXJZhZN4G9
A17: Harris Marc Helberg | B17: harris.helberg@bellsouth.net | C17: Discount | D17: 4 | E17: 15 | F17: 44246.21 | M17: https://dashboard.stripe.com/payments/pi_1IMR8EGWRsJ6qRMXM2cv2yMY
A18: Matthew Wyatt | B18: archiwyatt@gmail.com | C18: Discount | D18: 4 | E18: 15 | F18: 44260.91 | M18: https://dashboard.stripe.com/payments/pi_1IRlXjGWRsJ6qRMXz3KymtNH
